Workbook

Sheet Tasa de Capitalizacion
D2: Fecha de publicación modelo: | E2: 45674
C4: Cetes: | D4: =CONCATENATE("Útimos 60 meses al cierre del mes de "," ",TEXT(C15,"MMMM")," de ",TEXT(C15,"AAAA")) -> Útimos 60 meses al cierre del mes de noviembre de 2024
C5: INPC: | D5: =+C16 -> 45597
D7: Tipo de Bien | E7: Centros y Plazas Comerciales | F7: SELECCIONAR TIPO DE BIEN
D8: Edad Cronológica | E8: 8 | F8: INDICAR LA EDAD CRONOLÓGICA DEL AVALÚO
A10: Se muestra cálculo de tasa únicamente para fines de consulta y poder cotejar con el avalúo.
A13: Tasa de Capitalización
A14: Concepto | D14: %
A15: Cetes | B15: =+INPC!C332 -> 43770 | C15: =+INPC!D332 -> 45597 | D15: =CETES!F1357/100 -> 0.078352874
A16: Inflación | B16: =+INPC!C332 -> 43770 | C16: =+INPC!D332 -> 45597 | D16: =INPC!D331/100 -> 0.054233074
A17: Tasa Real | D17: =(D15-D16)/(1+D16) -> 0.022879001
A18: Edad Cronológica | D18: =$E$8 -> 8
A19: Vida Util Económica (VUE) | D19: =VLOOKUP(E7,'VUE - Vida Util Economica'!A4:M12,12,FALSE) -> 42
A20: Tasa Amortización | D20: =1/D19 -> 0.023809524
A21: Riesgo del sector | D21: 1.19
A22: Tasa de descuento | D22: =(D17+D20)*D21 -> 0.055559344
A23: Logaritmo (1+i) | D23: =LOG(1+D22) -> 0.023482655
A24: Tiempo de Recuperación de la Inversión | D24: =0.301/D23 -> 12.817972
A25: Tasa de Capitalización | D25: =(1/D24) -> 0.078015464

Sheet Indicadores para avaluos
D2: Fecha de publicación modelo: | E2: ='Tasa de Capitalizacion'!E2 -> 45674
C4: Cetes: | D4: ='Tasa de Capitalizacion'!D4 -> Útimos 60 meses al cierre del mes de noviembre de 2024
C5: INPC: | D5: ='Tasa de Capitalizacion'!D5 -> 45597
D7: Tipo de Bien | E7: =+'Tasa de Capitalizacion'!E7 -> Centros y Plazas Comerciales
D8: Edad Cronológica | E8: =+'Tasa de Capitalizacion'!E8 -> 8
A15: Indicadores para Tasa de Capitalización
A16: Concepto | B16: Fecha inicial | C16: Fecha final | D16: %
A17: Tasas a 5 años (60 meses)
A18: Cetes | B18: =CETES!E1358 -> 43802 | C18: =CETES!F1358 -> 45627 | D18: =CETES!F1357/100 -> 0.078352874
A19: Inflación | B19: =B18 -> 43802 | C19: =+C18 -> 45627 | D19: =INPC!D331/100 -> 0.054233074
A20: Vida Util Económica (VUE) | D20: =VLOOKUP('Tasa de Capitalizacion'!E7,'VUE - Vida Util Economica'!A4:M12,12,FALSE) -> 42
A21: Riesgo del sector | D21: ='Tasa de Capitalizacion'!D21 -> 1.19
A26: Indicadores para Resiudal Dinámico
A27: Concepto | B27: Fecha inicial | C27: Fecha final | D27: %
A28: Tasas a 20 años (240 meses)
A29: IPyC - Tasa de mercado (prom. 20 años) | B29: =CETES!$E$1370 -> 38327 | C29: =CETES!$F$1358 -> 45627 | D29: ='IPyC 2024'!C28 -> 0.085401537
A30: CETES 28 - Tasa libre de riesgo (prom. 20 años) | B30: =B29 -> 38327 | C30: =+C29 -> 45627 | D30: =CETES!F1369/100 -> 0.062379291
A31: Inflación (20 años) | B31: =+B30 -> 38327 | C31: =+C30 -> 45627 | D31: =INPC!D337/100 -> 0.043998465
A32: Riesgo del sector | D32: ='Tasa de Capitalizacion'!D21 -> 1.19
A35: Tasas a 1 año (12 meses)
A36: Tasa Interés Interbancaria de Equilibrio (TIIE 28 días) | B36: =CETES!E1364 -> 45262.583 | C36: =CETES!F1364 -> 45627 | D36: ='TIIE '!D2785/100 -> 0.11098798
A37: CETES 28 - Tasa Pasiva real (Promedio 12 meses) | B37: =$B$36 -> 45262.583 | C37: =+$C$36 -> 45627 | D37: =CETES!F1363/100 -> 0.10715577
A38: Inflación 12 meses | B38: =$B$36 -> 45262.583 | C38: =+$C$36 -> 45627 | D38: =INPC!D334/100 -> 0.042123394
A39: Margen Financiero de crédito puente | D39: 0.04
A40: Tasa Fiscal del Impuesto sobre la renta (ISR) | D40: 0.35
A44: Matriz de Vida Util Económica

Sheet VUE - Vida Util Economica
A1: Tasa de amortización
A3: TIPO DE BIEN | B3: EDAD | C3: EDAD CRONOLÓGICA MÁXIMA APLICACABLE | D3: P VRN | E3: % Curable | F3: %No Curable | G3: VUT | H3: VUR Curable | I3: VU No Curable | J3: Δm $ M y O | K3: VU Curable ⅟ VUE = (P2/ Δm) ⁰∙⁵ | L3: VUE | M3: TASA DE AMORTIZACION
A4: Nave Industrial/ Bodegas | B4: ='Tasa de Capitalizacion'!$D$18 -> 8 | C4: =IF(B4<=18,B4,"18") -> 8 | D4: 10000000 | E4: 0.4 | F4: 0.6 | G4: 50 | H4: =ROUND((G$4*E$4)-C4,0) -> 12 | I4: =ROUND((G$4*F$4),0) -> 30 | J4: =(D$4*E$4)/(H4-1) -> 363636.36 | K4: =((D$4*2)/J4)^0.5 -> 7.4161985 | L4: =ROUND((I4+K4),0) -> 37 | M4: =1/L4 -> 0.027027027
A5: Locales Comerciales y Oficinas | B5: ='Tasa de Capitalizacion'!$D$18 -> 8 | C5: =IF(B5<=28,B5,"28") -> 8 | D5: 10000000 | E5: 0.5 | F5: 0.5 | G5: 60 | H5: =ROUND((G$5*E$5)-C5,0) -> 22 | I5: =ROUND((G$5*F$5),0) -> 30 | J5: =(D$5*E$5)/(H5-1) -> 238095.24 | K5: =((D$5*2)/J5)^0.5 -> 9.1651514 | L5: =ROUND((I5+K5),0) -> 39 | M5: =1/L5 -> 0.025641026
A6: Centros y Plazas Comerciales | B6: ='Tasa de Capitalizacion'!$D$18 -> 8 | C6: =IF(B6<=25,B6,"25") -> 8 | D6: 10000000 | E6: 0.45 | F6: 0.55 | G6: 60 | H6: =ROUND((G$6*E$6)-C6,0) -> 19 | I6: =ROUND((G$6*F$6),0) -> 33 | J6: =(D$6*E$6)/(H6-1) -> 250000 | K6: =((D$6*2)/J6)^0.5 -> 8.9442719 | L6: =ROUND((I6+K6),0) -> 42 | M6: =1/L6 -> 0.023809524
A7: Viviendas | B7: ='Tasa de Capitalizacion'!$D$18 -> 8 | C7: =IF(B7<=35,B7,"35") -> 8 | D7: 10000000 | E7: 0.6 | F7: 0.4 | G7: 70 | H7: =ROUND((G$7*E$7)-C7,0) -> 34 | I7: =ROUND((G$7*F$7),0) -> 28 | J7: =(D$7*E$7)/(H7-1) -> 181818.18 | K7: =((D$7*2)/J7)^0.5 -> 10.488088 | L7: =ROUND((I7+K7),0) -> 38 | M7: =1/L7 -> 0.026315789
A8: Motel/Hotel 3 estrellas | B8: ='Tasa de Capitalizacion'!$D$18 -> 8 | C8: =IF(B8<=28,B8,"28") -> 8 | D8: 10000000 | E8: 0.6 | F8: 0.4 | G8: 60 | H8: =ROUND((G$8*E$8)-C8,0) -> 28 | I8: =ROUND((G$8*F$8),0) -> 24 | J8: =(D$8*E$8)/(H8-1) -> 222222.22 | K8: =((D$8*2)/J8)^0.5 -> 9.486833 | L8: =ROUND((I8+K8),0) -> 33 | M8: =1/L8 -> 0.03030303
A9: Hotel 4 estrellas | B9: ='Tasa de Capitalizacion'!$D$18 -> 8 | C9: =IF(B9<=34,B9,"34") -> 8 | D9: 10000000 | E9: 0.6 | F9: 0.4 | G9: 60 | H9: =ROUND((G$9*E$9)-C9,0) -> 28 | I9: =ROUND((G$9*F$9),0) -> 24 | J9: =(D$9*E$9)/(H9-1) -> 222222.22 | K9: =((D$9*2)/J9)^0.5 -> 9.486833 | L9: =ROUND((I9+K9),0) -> 33 | M9: =1/L9 -> 0.03030303
A10: Hotel 5 estrellas | B10: ='Tasa de Capitalizacion'!$D$18 -> 8 | C10: =IF(B10<=31,B10,"31") -> 8 | D10: 10000000 | E10: 0.55 | F10: 0.45 | G10: 60 | H10: =ROUND((G$10*E$10)-C10,0) -> 25 | I10: =ROUND((G$10*F$10),0) -> 27 | J10: =(D$10*E$10)/(H10-1) -> 229166.67 | K10: =((D$10*2)/J10)^0.5 -> 9.3419873 | L10: =ROUND((I10+K10),0) -> 36 | M10: =1/L10 -> 0.027777778
A11: Hotel Gran Turismo / Diamante | B11: ='Tasa de Capitalizacion'!$D$18 -> 8 | C11: =IF(B11<=47,B11,"47") -> 8 | D11: 10000000 | E11: 0.7 | F11: 0.3 | G11: 70 | H11: =ROUND((G$11*E$11)-C11,0) -> 41 | I11: =ROUND((G$11*F$11),0) -> 21 | J11: =(D$11*E$11)/(H11-1) -> 175000 | K11: =((D$11*2)/J11)^0.5 -> 10.69045 | L11: =ROUND((I11+K11),0) -> 32 | M11: =1/L11 -> 0.03125

Sheet Ecuacion de la tasa

Sheet CAPM WACC
X1: =+'Tasa de Capitalizacion'!D2 -> Fecha de publicación modelo: | Y1: =+'Tasa de Capitalizacion'!E2 -> 45674
A13: CAPM - WACC
A14: Datos para análisis | Q14: Tasa de Capital (CAPM)
A15: Concepto | H15: Sigla | J15: Nominal | K15: Inflación | N15: TASA REAL | Q15: Concepto | S15: Descripción | V15: Tasa
A16: IPyC - Tasa de mercado (prom. 20 años) | H16: Rm | J16: =E29 -> 0.085401537 | K16: =+$E$27 -> 0.043998465 | N16: =IF(((1+J16)-(1+K16))/(1+K16)<0,0,((1+J16)-(1+K16))/(1+K16)) -> 0.039658173 | Q16: Rm | S16: IPC 20 años | V16: =+N16 -> 0.039658173
A17: CETES 28 - Tasa libre de riesgo (prom. 20 años) | H17: Rf | J17: =E28 -> 0.062379291 | K17: =+$E$27 -> 0.043998465 | N17: =IF(((1+J17)-(1+K17))/(1+K17)<0,0,((1+J17)-(1+K17))/(1+K17)) -> 0.01760618 | Q17: Rf | S17: CETES 20 años | V17: =+N17 -> 0.01760618
A18: Beta - Factor de riesgo del sector | H18: β | J18: NA | K18: NA | N18: =+'Indicadores para avaluos'!D32 -> 1.19 | Q18: Rm - Rf | S18: Premio de mercado | V18: =+V16-V17 -> 0.022051992
A19: Tasa Interés Interbancaria de Equilibrio (28 días) | H19: TIIE | J19: =+L29 -> 0.11098798 | K19: =+L27 -> 0.042123394 | N19: =IF(((1+J19)-(1+K19))/(1+K19)<0,0,((1+J19)-(1+K19))/(1+K19)) -> 0.066081029 | Q19: Beta | S19: Riesgo del sector | V19: =+N18 -> 1.19
A20: TIIE + MF - Tasa activa real (Costo Financiero) | H20: Kd | J20: NA | K20: NA | N20: =N19+N22 -> 0.10608103 | Q20: (Rm-Rf) β | S20: Premio mercado c/riesgo | V20: =V18*V19 -> 0.026241871
A21: CETES 28 - Tasa Pasiva real (Promedio 12 meses) | J21: =+L28 -> 0.10715577 | K21: =+L27 -> 0.042123394 | N21: =IF(((1+J21)-(1+K21))/(1+K21)<0,0,((1+J21)-(1+K21))/(1+K21)) -> 0.062403719 | U21: Tasa de Capital = ((Rm-Rf) * β + Rf)) | V21: =V20+V17 -> 0.043848051
A22: Margen Financiero de crédito puente | H22: MF | J22: =+'Indicadores para avaluos'!D39 -> 0.04 | K22: NA | N22: =+J22 -> 0.04
A23: Tasa Fiscal del Impuesto sobre la renta (ISR) | H23: t | J23: 0.35 | K23: NA | N23: =J23 -> 0.35
A24: Índices | Q24: Tasa de descuento (WACC)
A25: 240 meses (20 años) | E25: ='Indicadores para avaluos'!B29 -> 38327 | G25: =+'Indicadores para avaluos'!C29 -> 45627 | I25: 12 meses (1 año) | L25: ='Indicadores para avaluos'!B36 -> 45262.583 | N25: ='Indicadores para avaluos'!C36 -> 45627 | Q25: Banda de Inversión
Q26: Capital | S26: Participación | V26: Beneficio Fiscal | Y26: Tasa Base | AB26: =AB31 -> APLICABLE
A27: Inflación | E27: ='Indicadores para avaluos'!D31 -> 0.043998465 | I27: Inflación | L27: ='Indicadores para avaluos'!D38 -> 0.042123394 | Q27: Prestado | S27: 0.6 | V27: 1 | Y27: =N20 -> 0.10608103 | AB27: =S27*V27*Y27 -> 0.063648617
A28: Cetes 28 | E28: ='Indicadores para avaluos'!D30 -> 0.062379291 | I28: Cetes 28 | L28: ='Indicadores para avaluos'!D37 -> 0.10715577 | Q28: Propio | S28: 0.4 | V28: N/A | Y28: =V21 -> 0.043848051 | AB28: =S28*Y28 -> 0.017539221
A29: IPyC | E29: ='Indicadores para avaluos'!D29 -> 0.085401537 | I29: TIIE 28 | L29: ='Indicadores para avaluos'!D36 -> 0.11098798 | Q29: Tasa de descuento anual aplicable en el flujo : | AB29: =SUM(AB27:AC28) -> 0.081187838
A30: Consolidación de tasas financieras aplicables por períodos
A31: Concepto | H31: Períodos del proyecto | AB31: APLICABLE
H32: Anuales | L32: Semestres | P32: Cuatrimestres | S32: Trimestres | V32: Bimestres | Y32: Mensual | AB32: Mensual
A33: Tasa activa real (TIIE + MF) Costo Financiero | H33: =N20 -> 0.10608103 | L33: =H33/2 -> 0.053040515 | P33: =+H33/3 -> 0.035360343 | S33: =H33/4 -> 0.026520257 | V33: =+H33/6 -> 0.017680172 | Y33: =H33/12 -> 0.0088400858 | AB33: =HLOOKUP(AB32,H32:AA35,2,0) -> 0.0088400858
A34: Tasa pasiva real (CETES 28) Prod. Fianciero | H34: =N21 -> 0.062403719 | L34: =H34/2 -> 0.03120186 | P34: =+H34/3 -> 0.02080124 | S34: =H34/4 -> 0.01560093 | V34: =+H34/6 -> 0.01040062 | Y34: =H34/12 -> 0.0052003099 | AB34: =HLOOKUP(AB32,H32:AA35,3,0) -> 0.0052003099
A35: Tasa de descuento | H35: =AB29 -> 0.081187838 | L35: =+H35/2 -> 0.040593919 | P35: =+H35/3 -> 0.027062613 | S35: =+H35/4 -> 0.02029696 | V35: =+H35/6 -> 0.013531306 | Y35: =(H35/12) -> 0.0067656532 | AB35: =HLOOKUP(AB32,H32:AA35,4,0) -> 0.0067656532
A36: Meses por periodo | H36: 12 | L36: 6 | P36: 4 | S36: 3 | V36: 2 | Y36: 1 | AB36: =HLOOKUP(AB32,H32:AA36,5,0) -> 1
AD289: =H32 -> Anuales
AD290: =+L32 -> Semestres
AD291: =+P32 -> Cuatrimestres
AD292: =+S32 -> Trimestres
AD293: =+V32 -> Bimestres
AD294: =+Y32 -> Mensual

Sheet CETES
A1: Banco de México
A3: Subastas y colocación de valores
A4: Valores Gubernamentales
A6: Fecha de consulta: 20/01/2025 01:27:07
A10: Título | B10: Valores gubernamentales Resultados de la subasta semanal, Tasa de rendimiento Cetes a 28 días
A11: Periodo disponible | B11: 02/09/1982 - 16/01/2025
A12: Periodicidad | B12: Diaria
A13: Cifra | B13: Porcentajes
A14: Unidad | B14: Porcentajes
A15: Base
A16: Aviso
A17: Tipo de información | B17: Niveles
A18: Fecha | B18: SF43936
A19: 36167 | B19: 29.29 | C19: 1
A20: 36174 | B20: 32.71 | C20: =+C19+1 -> 2
A21: 36181 | B21: 33.41 | C21: =+C20+1 -> 3
A22: 36188 | B22: 33.09 | C22: =+C21+1 -> 4
A23: 36195 | B23: 30.92 | C23: =+C22+1 -> 5
A24: 36202 | B24: 30.39 | C24: =+C23+1 -> 6
A25: 36209 | B25: 27 | C25: =+C24+1 -> 7
A26: 36216 | B26: 26.71 | C26: =+C25+1 -> 8
A27: 36223 | B27: 26.78 | C27: =+C26+1 -> 9
A28: 36230 | B28: 24.39 | C28: =+C27+1 -> 10
A29: 36237 | B29: 22.17 | C29: =+C28+1 -> 11
A30: 36244 | B30: 22.35 | C30: =+C29+1 -> 12
A31: 36250 | B31: 21.67 | C31: =+C30+1 -> 13
... A1290: 45064 | B1290: 11.25 | C1290: =+C1289+1 -> 1272
A1291: 45071 | B1291: 11.25 | C1291: =+C1290+1 -> 1273 | D1291: 60 | E1291: 43831
A1292: 45078 | B1292: 11.2 | C1292: =+C1291+1 -> 1274 | D1292: 59 | E1292: 43862
A1293: 45085 | B1293: 11.32 | C1293: =+C1292+1 -> 1275 | D1293: 58 | E1293: 43891
A1294: 45092 | B1294: 11.15 | C1294: =+C1293+1 -> 1276 | D1294: 57 | E1294: 43922
A1295: 45099 | B1295: 11.09 | C1295: =+C1294+1 -> 1277 | D1295: 56 | E1295: 43952
A1296: 45106 | B1296: 11.02 | C1296: =+C1295+1 -> 1278 | D1296: 55 | E1296: 43983
A1297: 45113 | B1297: 11.3 | C1297: =+C1296+1 -> 1279 | D1297: 54 | E1297: 44013
A1298: 45120 | B1298: 11.29 | C1298: =+C1297+1 -> 1280 | D1298: 53 | E1298: 44044
A1299: 45127 | B1299: 11.18 | C1299: =+C1298+1 -> 1281 | D1299: 52 | E1299: 44075
A1300: 45134 | B1300: 11.09 | C1300: =+C1299+1 -> 1282 | D1300: 51 | E1300: 44105
A1301: 45141 | B1301: 11.28 | C1301: =+C1300+1 -> 1283 | D1301: 50 | E1301: 44136
A1302: 45148 | B1302: 11.25 | C1302: =+C1301+1 -> 1284 | D1302: 49 | E1302: 44166
... A1348: 45470 | B1348: 10.88 | C1348: =+C1347+1 -> 1330 | D1348: 3 | E1348: 45566
...

Sheet INPC
A1: Banco de México
A3: Índices de Precios al Consumidor y UDIS
A4: Principales índices mensuales
A6: Fecha de consulta: 20/01/2025 01:29:43
A8: Aviso importante: Algunas de las series que está consultando registra un cambio, por favor consulte los metadatos de las mismas.
A10: Título | B10: IPC Por objeto del gasto Nacional, I n d i c e G e n e r a l
A11: Periodo disponible | B11: Ene 1969 - Dic 2024
A12: Periodicidad | B12: Mensual
A13: Cifra | B13: Indices
A14: Unidad | B14: Sin Unidad
A15: Base | B15: 2Q Jul 2018
A16: Aviso | B16: Acorde con la Ley del Sistema Nacional de Información Estadística y Geográfica, publicada en el Diario Oficial de la Federación el 16 de abril de 2008, a partir del 15 de julio de 2011 el Instituto Nacional de Estadística y Geografía (INEGI) tiene la facultad exclusiva de elaborar y publicar los índices nacionales de precios. En consideración a lo anterior, la información sobre la inflación referente a junio de 2011 fue la última publicada por el Banco de México. El INEGI comenzó la difusión de la información con los resultados correspondientes a la primera quincena de julio de 2011.
A17: Tipo de información | B17: Índices
A18: Fecha | B18: SP1
A19: 36161 | B19: 40.46977
A20: 36192 | B20: 41.013643
A21: 36220 | B21: 41.394684
A22: 36251 | B22: 41.774577
A23: 36281 | B23: 42.025877
A24: 36312 | B24: 42.302006
A25: 36342 | B25: 42.58158
A26: 36373 | B26: 42.821255
A27: 36404 | B27: 43.235018
A28: 36434 | B28: 43.508851
A29: 36465 | B29: 43.895776
A30: 36495 | B30: 44.335516
... A330: 45627 | B330: 137.949
C331: PROMEDIO GEOMÉTRICO 5 años | D331: =((B330/B270)^(1/5)-1)*100 -> 5.4233074
C332: =A269 -> 43770 | D332: =A329 -> 45597
C334: PROMEDIO GEOMÉTRICO 12 meses | D334: =((B330/B318)^(1/1)-1)*100 -> 4.2123394
C335: =A316 -> 45200 | D335: =+D332 -> 45597
C337: PROMEDIO GEOMÉTRICO 20 años (240 meses) | D337: =((B330/B90)^(1/20)-1)*100 -> 4.3998465
C338: =A88 -> 38261 | D338: =+D335 -> 45597
C340: http://www.banxico.org.mx/SieInternet/consultarDirectorioInternetAction.do?accion=consultarCuadro&idCuadro=CP154&locale=es
C341: https://www.inegi.org.mx/app/tabulados/default.aspx?nc=ca55_2018
C343: https://www.banxico.org.mx/SieInternet/consultarDirectorioInternetAction.do?accion=consultarCuadro&idCuadro=CP154&locale=es

Sheet TIIE 
A1: Banco de México
A3: Tasas y precios de referencia
A4: Tasas de Interés en el Mercado de Dinero
A6: Fecha de consulta: 20/01/2025 01:31:20
A10: Título | B10: TIIE a 28 días, Tasa de interés en por ciento anual
A11: Periodo disponible | B11: 23/03/1995 - 21/01/2025
A12: Periodicidad | B12: Diaria
A13: Cifra | B13: Porcentajes
A14: Unidad | B14: Sin Unidad
A15: Base
A16: Aviso
A17: Tipo de información | B17: Niveles
A18: Fecha | B18: SF43783
A19: 41641 | B19: 3.795
A20: 41642 | B20: 3.795
A21: 41645 | B21: 3.7925
A22: 41646 | B22: 3.7962
A23: 41647 | B23: 3.7994
A24: 41648 | B24: 3.8005
A25: 41649 | B25: 3.7927
A26: 41652 | B26: 3.7945
A27: 41653 | B27: 3.7972
A28: 41654 | B28: 3.7933
A29: 41655 | B29: 3.7843
A30: 41656 | B30: 3.7825
... A2782: 45653 | B2782: 10.2422
A2783: 45656 | B2783: 10.2429 | G2783: Cálculo de tasa Real
A2784: 45657 | B2784: 10.244 | G2784: TIIE 28 | H2784: =+D2785/100 -> 0.11098798 | O2784: =+B2385/100 -> 0.115057
C2785: TIIE ultimo año | D2785: =AVERAGE(B2534:B2784) -> 11.098798 | G2785: INFLACIÓN | H2785: =+INPC!D334/100 -> 0.042123394 | O2785: =+H2785 -> 0.042123394
C2786: =+CETES!E1364 -> 45262.583 | D2786: =+CETES!F1364 -> 45627 | G2786: TASA REAL | H2786: =(H2784-H2785)/(1+H2785) -> 0.066081029 | O2786: =(O2784-O2785)/(1+O2785) -> 0.069985576
C2788: https://www.banxico.org.mx/SieInternet/consultarDirectorioInternetAction.do?sector=18&accion=consultarCuadro&idCuadro=CF101&locale=es

Sheet IPyC 2024
A1: Indice de Precios y Cotizaciones S&P/BMV IPC (MXX)
A3: Matriz de precios
A4: Períodos | B4: 0 | C4: =+B4+1 -> 1 | D4: =+C4+1 -> 2 | E4: =+D4+1 -> 3 | F4: =+E4+1 -> 4 | G4: =+F4+1 -> 5 | H4: =+G4+1 -> 6 | I4: =+H4+1 -> 7 | J4: =+I4+1 -> 8 | ... V4: =+U4+1 -> 20
B5: 2004 | C5: 2005 | D5: 2006 | E5: 2007 | F5: 2008 | G5: 2009 | H5: 2010 | I5: 2011 | J5: 2012 | K5: 2013 | L5: 2014 | M5: 2015 | N5: 2016 | O5: 2017 | P5: 2018 | Q5: 2019 | R5: 2020 | S5: 2021 | T5: 2022 | U5: 2023 | V5: 2024
A6: Enero | B6: 9428.77 | C6: 13097.12 | D6: 18907.1 | E6: 27561.49 | F6: 28793.64 | G6: 19565.14 | H6: 30391.61 | I6: 36982.24 | J6: 37422.68 | K6: 45278.06 | L6: 40879.75 | M6: 40950.58 | N6: 43630.77 | O6: 47001.06 | P6: 50456.17 | Q6: 43987.94 | R6: 44108.31 | S6: 42985.73 | T6: 51330.85 | U6: 54564.27 | V6: 57372.76
A7: Febrero | B7: 9991.8 | C7: 13789.46 | D7: 18706.32 | E7: 26638.95 | F7: 28918.52 | G7: 17752.18 | H7: 31634.54 | I7: 37019.7 | J7: 37816.69 | K7: 44120.99 | L7: 38782.89 | M7: 44190.17 | N7: 43714.93 | O7: 46856.79 | P7: 47437.93 | Q7: 42823.81 | R7: 41324.31 | S7: 44592.91 | T7: 53400.61 | U7: 52758.06 | V7: 55414
A8: Marzo | B8: 10517.5 | C8: 12676.9 | D8: 19272.63 | E8: 28747.69 | F8: 30912.99 | G8: 19626.75 | H8: 33266.43 | I8: 37440.51 | J8: 39521.24 | K8: 44077.09 | L8: 40461.6 | M8: 43724.78 | N8: 45881.08 | O8: 48541.56 | P8: 46124.85 | Q8: 43281.28 | R8: 34554.53 | S8: 47246.26 | T8: 56536.68 | U8: 53904 | V8: 57369.01
A9: Abril | B9: 9948.13 | C9: 12322.99 | D9: 20646.19 | E9: 28996.71 | F9: 30281.41 | G9: 21898.85 | H9: 32687.32 | I9: 36962.62 | J9: 39461 | K9: 42263.48 | L9: 40711.56 | M9: 44582.39 | N9: 45784.77 | O9: 49261.33 | P9: 48358.16 | Q9: 44597.32 | R9: 36870.09 | S9: 48009.72 | T9: 51417.97 | U9: 55121.22 | V9: 56727.98
A10: Mayo | B10: 10036.29 | C10: 12964.39 | D10: 18677.92 | E10: 31398.96 | F10: 31975.47 | G10: 24331.71 | H10: 32038.53 | I10: 35832.79 | J10: 37872.95 | K10: 41588.32 | L10: 41362.51 | M10: 44703.62 | N10: 45459.45 | O10: 48788.44 | P10: 44662.55 | Q10: 42749.16 | R10: 36122.73 | S10: 50885.95 | T10: 51752.53 | U10: 52736.26 | V10: 55179.24
A11: Junio | B11: 10281.82 | C11: 13486.13 | D11: 19147.17 | E11: 31151.05 | F11: 29395.49 | G11: 24368.38 | H11: 31156.97 | I11: 36558.07 | J11: 40199.55 | K11: 40623.3 | L11: 42737.17 | M11: 45053.7 | N11: 45966.49 | O11: 49857.49 | P11: 47663.2 | Q11: 43161.17 | R11: 37716.43 | S11: 50289.75 | T11: 47524.45 | U11: 53526.1 | V11: 52440.02
A12: Julio | B12: 10116.39 | C12: 14409.66 | D12: 20095.93 | E12: 30659.66 | F12: 27501.02 | G12: 27043.5 | H12: 32308.74 | I12: 35999.34 | J12: 40704.28 | K12: 40837.88 | L12: 43817.69 | M12: 44752.93 | N12: 46660.67 | O12: 51011.87 | P12: 49698.01 | Q12: 40863.09 | R12: 37019.68 | S12: 50868.32 | T12: 48144.33 | U12: 54819.05 | V12: 53093.97
A13: Agosto | B13: 10264.32 | C13: 14243.19 | D13: 21049.35 | E13: 30347.86 | F13: 26290.99 | G13: 28129.95 | H13: 31679.85 | I13: 35721.1 | J13: 39421.65 | K13: 39484.46 | L13: 45628.09 | M13: 43721.96 | N13: 47541.32 | O13: 51210.48 | P13: 49547.68 | Q13: 42622.5 | R13: 36840.73 | S13: 53304.74 | T13: 44919.22 | U13: 53020.98 | V13: 51985.87
A14: Septiembre | B14: 10957.37 | C14: 16120.08 | D14: 21937.11 | E14: 30296.19 | F14: 24888.9 | G14: 29232.24 | H14: 33330.34 | I14: 33503.28 | J14: 40866.96 | K14: 40185.23 | L14: 44985.66 | M14: 42632.54 | N14: 47245.8 | O14: 50346.06 | P14: 49504.16 | Q14: 43011.27 | R14: 37458.69 | S14: 51385.55 | T14: 44626.8 | U14: 50874.98 | V14: 52477.3
A15: Octubre | B15: 11564.35 | C15: 15759.73 | D15: 23046.95 | E15: 31458.67 | F15: 20445.32 | G15: 28646.03 | H15: 35568.22 | I15: 36159.99 | J15: 41619.96 | K15: 41038.65 | L15: 45027.52 | M15: 44542.76 | N15: 48009.28 | O15: 48625.53 | P15: 43942.55 | Q15: 43337.28 | R15: 36987.86 | S15: 51309.84 | T15: 49922.3 | U15: 49061.88 | V15: 50661.05
A16: Noviembre | B16: 12102.55 | C16: 16830.96 | D16: 24962.01 | E16: 29770.52 | F16: 20534.72 | G16: 30957.11 | H16: 36817.32 | I16: 36829.15 | J16: 41833.52 | K16: 42499.13 | L16: 44190.47 | M16: 43418.55 | N16: 45315.96 | O16: 47092.44 | P16: 41732.78 | Q16: 42820.18 | R16: 41778.87 | S16: 49698.72 | T16: 51684.86 | U16: 54060.01 | V16: 49812.64
A17: Diciembre | B17: 12917.88 | C17: 17802.71 | D17: 26448.32 | E17: 29536.83 | F17: 22380.32 | G17: 32120.47 | H17: 38550.79 | I17: 37077.52 | J17: 43705.83 | K17: 42727.09 | L17: 43145.66 | M17: 42977.5 | N17: 45642.9 | O17: 49354.42 | P17: 41640.27 | Q17: 43541.02 | R17: 44066.88 | S17: 53272.44 | T17: 48463.86 | U17: 57386.25 | V17: 49513.27
A18: Fuente: | B18: https://mx.investing.com/indices/ipc-historical-data
B19: https://www.banxico.org.mx/SieInternet/consultarDirectorioInternetAction.do?accion=consultarCuadro&idCuadro=CF57&sector=7&locale=es
A20: Matriz de rentabilidades
A21: Mes en curso | B21: =B5 -> 2004 | C21: =C5 -> 2005 | D21: =D5 -> 2006 | E21: =E5 -> 2007 | F21: =F5 -> 2008 | G21: =G5 -> 2009 | H21: =H5 -> 2010 | I21: =I5 -> 2011 | ... V21: =V5 -> 2024
A22: Diciembre | B22: =VLOOKUP($A$22,($A$6:$V$17),2,FALSE) -> 12917.88 | C22: =VLOOKUP($A$22,($A$6:$V$17),3,FALSE) -> 17802.71 | D22: =VLOOKUP($A$22,($A$6:$V$17),4,FALSE) -> 26448.32 | E22: =VLOOKUP($A$22,($A$6:$V$17),5,FALSE) -> 29536.83 | F22: =VLOOKUP($A$22,($A$6:$V$17),6,FALSE) -> 22380.32 | G22: =VLOOKUP($A$22,($A$6:$V$17),7,FALSE) -> 32120.47 | H22: =VLOOKUP($A$22,($A$6:$V$17),8,FALSE) -> 38550.79 | I22: =VLOOKUP($A$22,($A$6:$V$17),9,FALSE) -> 37077.52 | J22: =VLOOKUP($A$22,($A$6:$V$17),10,FALSE) -> 43705.83 | K22: =VLOOKUP($A$22,($A$6:$V$17),11,FALSE) -> 42727.09 | L22: =VLOOKUP($A$22,($A$6:$V$17),12,FALSE) -> 43145.66 | M22: =VLOOKUP($A$22,($A$6:$V$17),13,FALSE) -> 42977.5 | N22: =VLOOKUP($A$22,($A$6:$V$17),14,FALSE) -> 45642.9 | O22: =VLOOKUP($A$22,($A$6:$V$17),15,FALSE) -> 49354.42 | P22: =VLOOKUP($A$22,($A$6:$V$17),16,FALSE) -> 41640.27 | Q22: =VLOOKUP($A$22,($A$6:$V$17),17,FALSE) -> 43541.02 | R22: =VLOOKUP($A$22,($A$6:$V$17),18,FALSE) -> 44066.88 | S22: =VLOOKUP($A$22,($A$6:$V$17),19,FALSE) -> 53272.44 | T22: =VLOOKUP($A$22,($A$6:$V$17),20,FALSE) -> 48463.86 | U22: =VLOOKUP($A$22,($A$6:$V$17),21,FALSE) -> 57386.25 | V22: =VLOOKUP($A$22,($A$6:$V$17),22,FALSE) -> 49513.27
B23: Promedio | C23: =(C22/B22)-1 -> 0.37814487 | D23: =(D22/C22)-1 -> 0.48563449 | E23: =(E22/D22)-1 -> 0.11677528 | F23: =(F22/E22)-1 -> -0.24229107 | G23: =(G22/F22)-1 -> 0.43521049 | H23: =(H22/G22)-1 -> 0.20019383 | I23: =(I22/H22)-1 -> -0.038216337 | J23: =(J22/I22)-1 -> 0.17876897 | ... V23: =(V22/U22)-1 -> -0.13719279
B24: LN | C24: =LN(C22/B22) -> 0.32073829 | D24: =LN(D22/C22) -> 0.39584195 | E24: =LN(E22/D22) -> 0.11044532 | F24: =LN(F22/E22) -> -0.27745596 | G24: =LN(G22/F22) -> 0.36131152 | H24: =LN(H22/G22) -> 0.18248307 | I24: =LN(I22/H22) -> -0.038965737 | J24: =LN(J22/I22) -> 0.16447065 | ... V24: =LN(V22/U22) -> -0.14756401
B25: Geométrico | C25: =V22/B22 -> 3.8329254 | D25: =((C25)^(1/V4))-1 -> 0.069489483
A27: Consolidación de Resultados
A28: Promedio aritmétrico | C28: =AVERAGE(C23:V23) -> 0.085401537
A29: Promedio LN | C29: =AVERAGE(C24:V24) -> 0.067181416
A30: Promedio Geométrico | C30: =((C25)^(1/V4))-1 -> 0.069489483
A34: Cálculo de tasa Real
A35: IPCy C | B35: =+C28 -> 0.085401537
A36: INFLACIÓN | B36: =+INPC!D337/100 -> 0.043998465
A37: TASA REAL | B37: =(B35-B36)/(1+B36) -> 0.039658173
